Workbook

Sheet Master Data
A1: ZC Invoice Num | B1: Customer Nbr | C1: Employee | D1: ZC Invoice Num | E1: Inv Date | F1: TS End | G1: Total Outstanding | H1: Invoice Amount
A2: ZNWT05815859 | B2: Wolters Kluwer ZCR- Kelly APC2 | C2: Adams,Celeste | D2: ZNWT05815859 | E2: 42314 | F2: 42309 | G2: 2373 | H2: 2373
A3: ZNWT05837260 | B3: Wolters Kluwer ZCR- Kelly APC2 | C3: Adams,Celeste | D3: ZNWT05837260 | E3: 42321 | F3: 42316 | G3: 2887.15 | H3: 2887.15
A4: ZNWT05867268 | B4: Wolters Kluwer ZCR- Kelly APC2 | C4: Adams,Celeste | D4: ZNWT05867268 | E4: 42328 | F4: 42323 | G4: 2373 | H4: 2373
A5: ZNWT05882338 | B5: Wolters Kluwer ZCR- Kelly APC2 | C5: Adams,Celeste | D5: ZNWT05882338 | E5: 42335 | F5: 42330 | G5: 2096.15 | H5: 2096.15
A6: ZNWT06254381 | B6: Wolters Kluwer ZCR- Kelly APC2 | C6: Adams,Celeste | D6: ZNWT06254381 | E6: 42342 | F6: 42337 | G6: 514.15 | H6: 514.15
A7: ZNWT06267795 | B7: Wolters Kluwer ZCR- Kelly APC2 | C7: Adams,Celeste | D7: ZNWT06267795 | E7: 42349 | F7: 42344 | G7: 2728.95 | H7: 2728.95
A8: ZNWT05614858 | B8: Wolters Kluwer ZCR- Kelly APC2 | C8: Allison,Stephanie | D8: ZNWT05614858 | E8: 42251 | F8: 42246 | G8: 0.35 | H8: 1009.82
A9: ZNWT05639677 | B9: Wolters Kluwer ZCR- Kelly APC2 | C9: Allison,Stephanie | D9: ZNWT05639677 | E9: 42258 | F9: 42253 | G9: 0.33 | H9: 951.28
A10: ZNWT05663233 | B10: Wolters Kluwer ZCR- Kelly APC2 | C10: Allison,Stephanie | D10: ZNWT05663233 | E10: 42265 | F10: 42260 | G10: 0.24 | H10: 724.43
A11: ZNWT05685666 | B11: Wolters Kluwer ZCR- Kelly APC2 | C11: Allison,Stephanie | D11: ZNWT05685666 | E11: 42272 | F11: 42267 | G11: 0.34 | H11: 970.89
A12: ZNWT05705837 | B12: Wolters Kluwer ZCR- Kelly APC2 | C12: Allison,Stephanie | D12: ZNWT05705837 | E12: 42279 | F12: 42274 | G12: 848.83 | H12: 848.83
A13: ZNWT05726413 | B13: Wolters Kluwer ZCR- Kelly APC2 | C13: Allison,Stephanie | D13: ZNWT05726413 | E13: 42286 | F13: 42281 | G13: 804.93 | H13: 804.93
... A55: ZNWT05240426 | B55: Wolters Kluwer ZCR- Kelly APC2 | C55: Anderson,Daniel | D55: ZNWT05240426 | E55: 42111 | F55: 42106 | G55: 2559.2 | H55: 2559.2
A56: ZNWE00359228 | B56: Wolters Kluwer ZCR- Kelly APC2 | C56: Anderson,Daniel | D56: ZNWE00359228 | E56: 42041 | G56: 1484.7 | H56: 1484.7
A57: ZNWE00365239 | B57: Wolters Kluwer ZCR- Kelly APC2 | C57: Anderson,Daniel | D57: ZNWE00365239 | E57: 42104 | G57: 1089.89 | H57: 1089.89
A58: ZNWE00366081 | B58: Wolters Kluwer ZCR- Kelly APC2 | C58: Anderson,Daniel | D58: ZNWE00366081 | E58: 42114 | G58: 3260.37 | H58: 3260.37
A59: ZNWT05222590 | B59: Wolters Kluwer ZCR- Kelly APC2 | C59: Andos III,Nicholas | D59: ZNWT05222590 | E59: 42104 | F59: 42099 | G59: 2149.77 | H59: 2149.77
A60: ZNWT05240471 | B60: Wolters Kluwer ZCR- Kelly APC2 | C60: Andos III,Nicholas | D60: ZNWT05240471 | E60: 42111 | F60: 42106 | G60: 4299.54 | H60: 4299.54
A61: ZNWT05258530 | B61: Wolters Kluwer ZCR- Kelly APC2 | C61: Andos III,Nicholas | D61: ZNWT05258530 | E61: 42118 | F61: 42113 | G61: 4094.8 | H61: 4094.8
A62: ZNWT05769720 | B62: Wolters Kluwer ZCR- Kelly APC2 | C62: Andos III,Nicholas | D62: ZNWT05769720 | E62: 42300 | F62: 42295 | G62: 4094.8 | H62: 4094.8
A63: ZNWT05791597 | B63: Wolters Kluwer ZCR- Kelly APC2 | C63: Andos III,Nicholas | D63: ZNWT05791597 | E63: 42307 | F63: 42302 | G63: 4504.28 | H63: 4504.28
A64: ZNWT05815870 | B64: Wolters Kluwer ZCR- Kelly APC2 | C64: Andos III,Nicholas | D64: ZNWT05815870 | E64: 42314 | F64: 42309 | G64: 4504.28 | H64: 4504.28
A65: ZNWT05837282 | B65: Wolters Kluwer ZCR- Kelly APC2 | C65: Andos III,Nicholas | D65: ZNWT05837282 | E65: 42321 | F65: 42316 | G65: 4401.91 | H65: 4401.91
A66: ZNWT05859728 | B66: Wolters Kluwer ZCR- Kelly APC2 | C66: Andos III,Nicholas | D66: ZNWT05859728 | E66: 42328 | F66: 42323 | G66: 4094.8 | H66: 4094.8
A67: ZNWT05882433 | B67: Wolters Kluwer ZCR- Kelly APC2 | C67: Andos III,Nicholas | D67: ZNWT05882433 | E67: 42335 | F67: 42330 | G67: 4504.28 | H67: 4504.28
A68: ZNWT06267669 | B68: Wolters Kluwer ZCR- Kelly APC2 | C68: Andos III,Nicholas | D68: ZNWT06267669 | E68: 42349 | F68: 42337 | G68: 2968.73 | H68: 2968.73
A69: ZNWT05595686 | B69: Wolters Kluwer ZCR- Kelly APC2 | C69: Andrews,Laura | D69: ZNWT05595686 | E69: 42244 | F69: 42232 | G69: 225.6 | H69: 225.6
A70: ZNWT05614873 | B70: Wolters Kluwer ZCR- Kelly APC2 | C70: Andrews,Laura | D70: ZNWT05614873 | E70: 42251 | F70: 42246 | G70: 225.6 | H70: 225.6
... A100: ZNWT05058404 | B100: Wolters Kluwer ZCR- Kelly APC2 | C100: Ashby,Susan | D100: ZNWT05058404 | E100: 42041 | F100: 42036 | G100: 417.01 | H100: 417.01

Sheet VLOOKUP
A1: Customer Nbr | B1: Employee | C1: ZC Invoice Num | D1: Inv Date | E1: TS End | F1: Consolidated Invoice | G1: Total Outstanding | H1: Invoice Amount
A2: =VLOOKUP(C2,'Master Data'!A1:H100,2,FALSE) -> Wolters Kluwer ZCR- Kelly APC2 | B2: =VLOOKUP(C2,'Master Data'!A1:H100,3,FALSE) -> Adams,Celeste | C2: ZNWT06254381 | D2: =VLOOKUP(C2,'Master Data'!A1:H100,5,FALSE) -> 42342 | E2: =VLOOKUP(C2,'Master Data'!A1:H100,6,FALSE) -> 42337 | F2: (Leave Blank if not given in Master Data) | G2: =VLOOKUP(C2,'Master Data'!D2:G100,4,0) -> 514.15 | H2: =VLOOKUP(C2,'Master Data'!D2:H100,5,0) -> 514.15 | J2: Instruction
A3: =VLOOKUP(C3,'Master Data'!A2:H101,2,FALSE) -> Wolters Kluwer ZCR- Kelly APC2 | B3: =VLOOKUP(C3,'Master Data'!A2:H101,3,FALSE) -> Alvord,Maria | C3: ZNWT05867243 | D3: =VLOOKUP(C3,'Master Data'!A2:H101,5,FALSE) -> 42328 | E3: =VLOOKUP(C3,'Master Data'!A2:H101,6,FALSE) -> 42323 | G3: =VLOOKUP(C3,'Master Data'!D3:G101,4,0) -> 73.15 | H3: =VLOOKUP(C3,'Master Data'!D3:H101,5,0) -> 73.15
A4: =VLOOKUP(C4,'Master Data'!A3:H102,2,FALSE) -> Wolters Kluwer ZCR- Kelly APC2 | B4: =VLOOKUP(C4,'Master Data'!A3:H102,3,FALSE) -> Anderson,Daniel | C4: ZNWT05011433 | D4: =VLOOKUP(C4,'Master Data'!A3:H102,5,FALSE) -> 42027 | E4: =VLOOKUP(C4,'Master Data'!A3:H102,6,FALSE) -> 42022 | G4: =VLOOKUP(C4,'Master Data'!D4:G102,4,0) -> 12.4 | H4: =VLOOKUP(C4,'Master Data'!D4:H102,5,0) -> 2559.2 | J4: Pull required data from Master Data tab using Vlookup for below Invoices
A5: =VLOOKUP(C5,'Master Data'!A4:H103,2,FALSE) -> Wolters Kluwer ZCR- Kelly APC2 | B5: =VLOOKUP(C5,'Master Data'!A4:H103,3,FALSE) -> Anderson,Daniel | C5: ZNWT05052243 | D5: =VLOOKUP(C5,'Master Data'!A4:H103,5,FALSE) -> 42041 | E5: =VLOOKUP(C5,'Master Data'!A4:H103,6,FALSE) -> 42036 | G5: =VLOOKUP(C5,'Master Data'!D5:G103,4,0) -> 2559.2 | H5: =VLOOKUP(C5,'Master Data'!D5:H103,5,0) -> 2559.2 | J5: ZNWT06254381
A6: =VLOOKUP(C6,'Master Data'!A5:H104,2,FALSE) -> Wolters Kluwer ZCR- Kelly APC2 | B6: =VLOOKUP(C6,'Master Data'!A5:H104,3,FALSE) -> Andos III,Nicholas | C6: ZNWT05882433 | D6: =VLOOKUP(C6,'Master Data'!A5:H104,5,FALSE) -> 42335 | E6: =VLOOKUP(C6,'Master Data'!A5:H104,6,FALSE) -> 42330 | G6: =VLOOKUP(C6,'Master Data'!D6:G104,4,0) -> 4504.28 | H6: =VLOOKUP(C6,'Master Data'!D6:H104,5,0) -> 4504.28 | J6: ZNWT05867243
A7: =VLOOKUP(C7,'Master Data'!A6:H105,2,FALSE) -> Wolters Kluwer ZCR- Kelly APC2 | B7: =VLOOKUP(C7,'Master Data'!A6:H105,3,FALSE) -> Andrews,Laura | C7: ZNWT06254363 | D7: =VLOOKUP(C7,'Master Data'!A6:H105,5,FALSE) -> 42342 | E7: =VLOOKUP(C7,'Master Data'!A6:H105,6,FALSE) -> 42337 | G7: =VLOOKUP(C7,'Master Data'!D7:G105,4,0) -> 225.6 | H7: =VLOOKUP(C7,'Master Data'!D7:H105,5,0) -> 225.6 | J7: ZNWT05011433
A8: =VLOOKUP(C8,'Master Data'!A7:H106,2,FALSE) -> Wolters Kluwer ZCR- Kelly APC2 | B8: =VLOOKUP(C8,'Master Data'!A7:H106,3,FALSE) -> Archuleta,Jennifer | C8: ZNWT06267843 | D8: =VLOOKUP(C8,'Master Data'!A7:H106,5,FALSE) -> 42349 | E8: =VLOOKUP(C8,'Master Data'!A7:H106,6,FALSE) -> 42344 | G8: =VLOOKUP(C8,'Master Data'!D8:G106,4,0) -> 192.08 | H8: =VLOOKUP(C8,'Master Data'!D8:H106,5,0) -> 192.08 | J8: ZNWT05052243
A9: =VLOOKUP(C9,'Master Data'!A8:H107,2,FALSE) -> Wolters Kluwer ZCR- Kelly APC2 | B9: =VLOOKUP(C9,'Master Data'!A8:H107,3,FALSE) -> Anderson,Daniel | C9: ZNWT05204198 | D9: =VLOOKUP(C9,'Master Data'!A8:H107,5,FALSE) -> 42097 | E9: =VLOOKUP(C9,'Master Data'!A8:H107,6,FALSE) -> 42092 | G9: =VLOOKUP(C9,'Master Data'!D9:G107,4,0) -> 2559.2 | H9: =VLOOKUP(C9,'Master Data'!D9:H107,5,0) -> 2559.2 | J9: ZNWT05882433
J10: ZNWT06254363
J11: ZNWT06267843
J12: ZNWT05204198

Sheet Delimited
A1: Employee | C1: First Name | D1: Last Name | F1: Instruction
A2: Adams,Celeste | C2: Adams | D2: Celeste
A3: Allison,Daniel | C3: Allison | D3: Daniel | F3: Separate Employee name using "Delimited"
A4: Alvarez,Mukhai | C4: Alvarez | D4: Mukhai
A5: Alvord,Jennifer | C5: Alvord | D5: Jennifer | F5: Output
A6: Anderson,Laura | C6: Anderson | D6: Laura | F6: First Name | G6: Last Name
A7: Andos,Maria | C7: Andos | D7: Maria | F7: Adams | G7: Celeste
A8: Andrews,Michelle | C8: Andrews | D8: Michelle
A9: Ankrah,Sally | C9: Ankrah | D9: Sally
A10: Archuleta,Stephanie | C10: Archuleta | D10: Stephanie
A11: Arden,Susan | C11: Arden | D11: Susan
A12: Ashby,Ankrah | C12: Ashby | D12: Ankrah
A13: Adams,Daniel | C13: Adams | D13: Daniel
A14: Allison,Mukhai | C14: Allison | D14: Mukhai
A15: Alvarez,Jennifer | C15: Alvarez | D15: Jennifer
A16: Alvord,Laura | C16: Alvord | D16: Laura
A17: Anderson,Maria | C17: Anderson | D17: Maria
A18: Andos,Michelle | C18: Andos | D18: Michelle
A19: Andrews,Sally | C19: Andrews | D19: Sally
... A47: Archuleta,Susan | C47: Archuleta | D47: Susan

Sheet CONCATENATE
A1: First Name | B1: Last Name | D1: Concat | F1: TextJoin | I1: Instruction
A2: Adams | B2: Alvord | D2: =_xlfn.CONCAT(A2,",",B2) -> Adams,Alvord | F2: =_xlfn.TEXTJOIN(",",1,A2,B2) -> Adams,Alvord
A3: Allison | B3: Celeste | D3: =_xlfn.CONCAT(A3,",",B3) -> Allison,Celeste | F3: =_xlfn.TEXTJOIN(",",1,A3,B3) -> Allison,Celeste | I3: Merge Employee name using "CONCATENATE" method
A4: Alvarez | B4: Daniel | D4: =_xlfn.CONCAT(A4,",",B4) -> Alvarez,Daniel | F4: =_xlfn.TEXTJOIN(",",1,A4,B4) -> Alvarez,Daniel
A5: Alvord | B5: Jennifer | D5: =_xlfn.CONCAT(A5,",",B5) -> Alvord,Jennifer | F5: =_xlfn.TEXTJOIN(",",1,A5,B5) -> Alvord,Jennifer | I5: Output
A6: Anderson | B6: Laura | D6: =_xlfn.CONCAT(A6,",",B6) -> Anderson,Laura | F6: =_xlfn.TEXTJOIN(",",1,A6,B6) -> Anderson,Laura | I6: Adams,Celeste
A7: Andos III | B7: Maria | D7: =_xlfn.CONCAT(A7,",",B7) -> Andos III,Maria | F7: =_xlfn.TEXTJOIN(",",1,A7,B7) -> Andos III,Maria
A8: Andrews | B8: Michelle | D8: =_xlfn.CONCAT(A8,",",B8) -> Andrews,Michelle | F8: =_xlfn.TEXTJOIN(",",1,A8,B8) -> Andrews,Michelle
A9: Ankrah | B9: Nicholas | D9: =_xlfn.CONCAT(A9,",",B9) -> Ankrah,Nicholas | F9: =_xlfn.TEXTJOIN(",",1,A9,B9) -> Ankrah,Nicholas
A10: Archuleta | B10: Sally | D10: =_xlfn.CONCAT(A10,",",B10) -> Archuleta,Sally | F10: =_xlfn.TEXTJOIN(",",1,A10,B10) -> Archuleta,Sally
A11: Arden | B11: Stephanie | D11: =_xlfn.CONCAT(A11,",",B11) -> Arden,Stephanie | F11: =_xlfn.TEXTJOIN(",",1,A11,B11) -> Arden,Stephanie
A12: Ashby | B12: Susan | D12: =_xlfn.CONCAT(A12,",",B12) -> Ashby,Susan | F12: =_xlfn.TEXTJOIN(",",1,A12,B12) -> Ashby,Susan
A13: Daniel | B13: Adams | D13: =_xlfn.CONCAT(A13,",",B13) -> Daniel,Adams | F13: =_xlfn.TEXTJOIN(",",1,A13,B13) -> Daniel,Adams
A14: Jennifer | B14: Allison | D14: =_xlfn.CONCAT(A14,",",B14) -> Jennifer,Allison | F14: =_xlfn.TEXTJOIN(",",1,A14,B14) -> Jennifer,Allison
A15: Laura | B15: Alvarez | D15: =_xlfn.CONCAT(A15,",",B15) -> Laura,Alvarez | F15: =_xlfn.TEXTJOIN(",",1,A15,B15) -> Laura,Alvarez
A16: Maria | B16: Alvord | D16: =_xlfn.CONCAT(A16,",",B16) -> Maria,Alvord | F16: =_xlfn.TEXTJOIN(",",1,A16,B16) -> Maria,Alvord
A17: Michelle | B17: Anderson | D17: =_xlfn.CONCAT(A17,",",B17) -> Michelle,Anderson | F17: =_xlfn.TEXTJOIN(",",1,A17,B17) -> Michelle,Anderson
A18: Nicholas | B18: Andos III | D18: =_xlfn.CONCAT(A18,",",B18) -> Nicholas,Andos III | F18: =_xlfn.TEXTJOIN(",",1,A18,B18) -> Nicholas,Andos III
... A27: Adams | B27: Andrews | D27: =_xlfn.CONCAT(A27,",",B27) -> Adams,Andrews | F27: =_xlfn.TEXTJOIN(",",1,A27,B27) -> Adams,Andrews

Sheet Pivot
A1: Customer Nbr | B1: Employee | C1: ZC Invoice Num | D1: Inv Date | E1: TS End | F1: Total Outstanding | G1: Invoice Amount | J1: Instruction
A2: Wolters Kluwer ZCR- Kelly APC2 | B2: Adams,Celeste | C2: ZNWT05815859 | D2: 42314 | E2: 42309 | F2: 2373 | G2: 2373
A3: Wolters Kluwer ZCR- Kelly APC2 | B3: Allison,Stephanie | C3: ZNWT05614858 | D3: 42251 | E3: 42246 | F3: 0.35 | G3: 1009.82
A4: Wolters Kluwer ZCR- Kelly APC2 | B4: Alvarez,Jennifer | C4: ZNWT05615002 | D4: 42251 | E4: 42246 | F4: 860.54 | G4: 860.54
A5: Wolters Kluwer ZCR- Kelly APC2 | B5: Alvord,Maria | C5: ZNWT05557012 | D5: 42230 | E5: 42218 | F5: 135.33 | G5: 135.33 | J5: find Duplicate value using Pivot Tab
A6: Wolters Kluwer ZCR- Kelly APC2 | B6: Anderson,Daniel | C6: ZNWT04993484 | D6: 42020 | E6: 42015 | F6: 12.4 | G6: 2559.2
A7: Wolters Kluwer ZCR- Kelly APC2 | B7: Andos III,Nicholas | C7: ZNWT05222590 | D7: 42104 | E7: 42099 | F7: 2149.77 | G7: 2149.77
A8: Wolters Kluwer ZCR- Kelly APC2 | B8: Andrews,Laura | C8: ZNWT05595686 | D8: 42244 | E8: 42232 | F8: 225.6 | G8: 225.6
A9: Wolters Kluwer ZCR- Kelly APC2 | B9: Ankrah,Michelle | C9: ZNWT05204231 | D9: 42097 | E9: 42092 | F9: 75.25 | G9: 75.25
A10: Wolters Kluwer ZCR- Kelly APC2 | B10: Archuleta,Jennifer | C10: ZNWT05837162 | D10: 42321 | E10: 42288 | F10: 204.88 | G10: 204.88
A11: Wolters Kluwer ZCR- Kelly APC2 | B11: Arden,Sally | C11: ZNWT05576293 | D11: 42237 | E11: 42211 | F11: 0.04 | G11: 112.2
A12: Wolters Kluwer ZCR- Kelly APC2 | B12: Ashby,Susan | C12: ZNWT05058404 | D12: 42041 | E12: 42036 | F12: 417.01 | G12: 417.01
A13: Wolters Kluwer ZCR- Kelly APC2 | B13: Ashby,Susan | C13: ZNWT04993484 | D13: 42286 | E13: 42281 | F13: 804.93 | G13: 804.93
A16: ZC Invoice Num | B16: Count of ZC Invoice Num
A17: ZNWT04993484 | B17: 2
A18: ZNWT05058404 | B18: 1
A19: ZNWT05204231 | B19: 1
A20: ZNWT05222590 | B20: 1
A21: ZNWT05557012 | B21: 1
A22: ZNWT05576293 | B22: 1
A23: ZNWT05595686 | B23: 1
A24: ZNWT05614858 | B24: 1
A25: ZNWT05615002 | B25: 1
A26: ZNWT05815859 | B26: 1
A27: ZNWT05837162 | B27: 1
A28: Grand Total | B28: 12

Sheet Sub Total
A1: Customer Nbr | B1: Employee | C1: ZC Invoice Num | D1: Inv Date | E1: TS End | F1: Total Outstanding | G1: Invoice Amount
A2: Wolters Kluwer ZCR- Kelly APC2 | B2: Adams,Celeste | C2: ZNWT05815859 | D2: 42314 | E2: 42309 | F2: 2373 | G2: 2373 | K2: Instruction
A3: Wolters Kluwer ZCR- Kelly APC2 | B3: Adams,Celeste | C3: ZNWT05837260 | D3: 42321 | E3: 42316 | F3: 2887.15 | G3: 2887.15 | K3: Create a sub total of total Outstanding and Invoice Amount for each Employee Name in this tab
A4: Wolters Kluwer ZCR- Kelly APC2 | B4: Adams,Celeste | C4: ZNWT05867268 | D4: 42328 | E4: 42323 | F4: 2373 | G4: 2373
A5: Wolters Kluwer ZCR- Kelly APC2 | B5: Adams,Celeste | C5: ZNWT05882338 | D5: 42335 | E5: 42330 | F5: 2096.15 | G5: 2096.15
A6: Wolters Kluwer ZCR- Kelly APC2 | B6: Adams,Celeste | C6: ZNWT06254381 | D6: 42342 | E6: 42337 | F6: 514.15 | G6: 514.15
A7: Wolters Kluwer ZCR- Kelly APC2 | B7: Adams,Celeste | C7: ZNWT06267795 | D7: 42349 | E7: 42344 | F7: 2728.95 | G7: 2728.95
B8: Adams,Celeste Total | F8: =SUBTOTAL(9,F2:F7) -> 12972.4 | G8: =SUBTOTAL(9,G2:G7) -> 12972.4
A9: Wolters Kluwer ZCR- Kelly APC2 | B9: Allison,Stephanie | C9: ZNWT05614858 | D9: 42251 | E9: 42246 | F9: 0.35 | G9: 1009.82
A10: Wolters Kluwer ZCR- Kelly APC2 | B10: Allison,Stephanie | C10: ZNWT05639677 | D10: 42258 | E10: 42253 | F10: 0.33 | G10: 951.28
A11: Wolters Kluwer ZCR- Kelly APC2 | B11: Allison,Stephanie | C11: ZNWT05663233 | D11: 42265 | E11: 42260 | F11: 0.24 | G11: 724.43
A12: Wolters Kluwer ZCR- Kelly APC2 | B12: Allison,Stephanie | C12: ZNWT05685666 | D12: 42272 | E12: 42267 | F12: 0.34 | G12: 970.89
A13: Wolters Kluwer ZCR- Kelly APC2 | B13: Allison,Stephanie | C13: ZNWT05705837 | D13: 42279 | E13: 42274 | F13: 848.83 | G13: 848.83
A14: Wolters Kluwer ZCR- Kelly APC2 | B14: Allison,Stephanie | C14: ZNWT05726413 | D14: 42286 | E14: 42281 | F14: 804.93 | G14: 804.93
A15: Wolters Kluwer ZCR- Kelly APC2 | B15: Allison,Stephanie | C15: ZNWT05748250 | D15: 42293 | E15: 42288 | F15: 746.39 | G15: 746.39
A16: Wolters Kluwer ZCR- Kelly APC2 | B16: Allison,Stephanie | C16: ZNWT05769700 | D16: 42300 | E16: 42295 | F16: 875.47 | G16: 875.47
A17: Wolters Kluwer ZCR- Kelly APC2 | B17: Allison,Stephanie | C17: ZNWT05791605 | D17: 42307 | E17: 42302 | F17: 939.27 | G17: 939.27
A18: Wolters Kluwer ZCR- Kelly APC2 | B18: Allison,Stephanie | C18: ZNWT05815817 | D18: 42314 | E18: 42309 | F18: 831.85 | G18: 831.85
A19: Wolters Kluwer ZCR- Kelly APC2 | B19: Allison,Stephanie | C19: ZNWT05837238 | D19: 42321 | E19: 42316 | F19: 853.81 | G19: 853.81
A20: Wolters Kluwer ZCR- Kelly APC2 | B20: Allison,Stephanie | C20: ZNWT05859737 | D20: 42328 | E20: 42323 | F20: 790.29 | G20: 790.29
... A23: Wolters Kluwer ZCR- Kelly APC2 | B23: Allison,Stephanie | C23: ZNWT06267805 | D23: 42349 | E23: 42344 | F23: 1061.04 | G23: 1061.04
B24: Allison,Stephanie Total | F24: =SUBTOTAL(9,F9:F23) -> 9255.57 | G24: =SUBTOTAL(9,G9:G23) -> 12910.73
A25: Wolters Kluwer ZCR- Kelly APC2 | B25: Alvarez,Jennifer | C25: ZNWT05615002 | D25: 42251 | E25: 42246 | F25: 860.54 | G25: 860.54
A26: Wolters Kluwer ZCR- Kelly APC2 | B26: Alvarez,Jennifer | C26: ZNWT05639579 | D26: 42258 | E26: 42253 | F26: 779.99 | G26: 779.99
A27: Wolters Kluwer ZCR- Kelly APC2 | B27: Alvarez,Jennifer | C27: ZNWT05705703 | D27: 42279 | E27: 42274 | F27: 770.66 | G27: 770.66
A28: Wolters Kluwer ZCR- Kelly APC2 | B28: Alvarez,Jennifer | C28: ZNWT05769747 | D28: 42300 | E28: 42295 | F28: 480.81 | G28: 480.81
A29: Wolters Kluwer ZCR- Kelly APC2 | B29: Alvarez,Jennifer | C29: ZNWT05791629 | D29: 42307 | E29: 42302 | F29: 823.53 | G29: 823.53
A30: Wolters Kluwer ZCR- Kelly APC2 | B30: Alvarez,Jennifer | C30: ZNWT05823513 | D30: 42314 | E30: 42309 | F30: 724.01 | G30: 724.01
A31: Wolters Kluwer ZCR- Kelly APC2 | B31: Alvarez,Jennifer | C31: ZNWT05837200 | D31: 42321 | E31: 42316 | F31: 958.5 | G31: 958.5
A32: Wolters Kluwer ZCR- Kelly APC2 | B32: Alvarez,Jennifer | C32: ZNWT05867264 | D32: 42328 | E32: 42323 | F32: 347.7 | G32: 347.7
A33: Wolters Kluwer ZCR- Kelly APC2 | B33: Alvarez,Jennifer | C33: ZNWT05882455 | D33: 42335 | E33: 42330 | F33: 1064.86 | G33: 1064.86
A34: Wolters Kluwer ZCR- Kelly APC2 | B34: Alvarez,Jennifer | C34: ZNWT05892571 | D34: 42342 | E34: 42337 | F34: 406.79 | G34: 406.79
A35: Wolters Kluwer ZCR- Kelly APC2 | B35: Alvarez,Jennifer | C35: ZNWT06267736 | D35: 42349 | E35: 42344 | F35: 633.82 | G35: 633.82
B36: Alvarez,Jennifer Total | F36: =SUBTOTAL(9,F25:F35) -> 7851.21 | G36: =SUBTOTAL(9,G25:G35) -> 7851.21
A37: Wolters Kluwer ZCR- Kelly APC2 | B37: Alvord,Maria | C37: ZNWT05557012 | D37: 42230 | E37: 42218 | F37: 135.33 | G37: 135.33
A38: Wolters Kluwer ZCR- Kelly APC2 | B38: Alvord,Maria | C38: ZNWT05614847 | D38: 42251 | E38: 42239 | F38: 76.81 | G38: 76.81
A39: Wolters Kluwer ZCR- Kelly APC2 | B39: Alvord,Maria | C39: ZNWT05614936 | D39: 42251 | E39: 42246 | F39: 62.18 | G39: 62.18
A40: Wolters Kluwer ZCR- Kelly APC2 | B40: Alvord,Maria | C40: ZNWT05639716 | D40: 42258 | E40: 42253 | F40: 87.78 | G40: 87.78
A41: Wolters Kluwer ZCR- Kelly APC2 | B41: Alvord,Maria | C41: ZNWT05705808 | D41: 42279 | E41: 42267 | F41: 80.47 | G41: 80.47
A42: Wolters Kluwer ZCR- Kelly APC2 | B42: Alvord,Maria | C42: ZNWT05705704 | D42: 42279 | E42: 42274 | F42: 124.36 | G42: 124.36
...

Sheet Chart
A1: Employee | B1: 2014 | C1: 2015 | D1: 2016 | E1: 2017 | F1: 2018 | I1: Employee | J1: Sum of 2014 | K1: Sum of 2015 | L1: Sum of 2016 | M1: Sum of 2017 | N1: Sum of 2018
A2: Adams,Alvord | B2: 112.2 | C2: 148.38 | D2: 129.03 | E2: 148.38 | F2: 170.64 | I2: Adams,Alvord | J2: 112.2 | K2: 148.38 | L2: 129.03 | M2: 148.38 | N2: 170.64
A3: Alvord,Jennifer | B3: 56.1 | C3: 270.95 | D3: 64.52 | E3: 74.19 | F3: 85.32 | I3: Alvord,Jennifer | J3: 56.1 | K3: 270.95 | L3: 64.52 | M3: 74.19 | N3: 85.32
A4: Jitendra,Chauhan | B4: 112.2 | C4: 321.76 | D4: 129.03 | E4: 148.38 | F4: 170.64 | I4: Arden,Stephanie | J4: 192.08 | K4: 204.88 | L4: 220.89 | M4: 254.03 | N4: 292.13
A5: Arden,Stephanie | B5: 192.08 | C5: 204.88 | D5: 220.89 | E5: 254.03 | F5: 292.13 | I5: Grand Total | J5: 360.38 | K5: 624.21 | L5: 414.44 | M5: 476.6 | N5: 548.09
A8: Please create Chart as per below
